<?xml version="1.0" encoding="utf-8"?>
<robot name="assistbot" xmlns:xacro="http://ros.org/wiki/xacro">
    <link name="base_footprint"/>
    <link name="imu_link"/>
    <link name="base_link">
        <inertial>
            <origin xyz="-0.0304416859098744 4.23384368655101E-05 0.0448234503408059" rpy="0 0 0"/>
            <mass value="1.0754239466482"/>
            <inertia
                    ixx="0.0208831789264125"
                    ixy="2.4618093127858E-06"
                    ixz="0.00616019290028669"
                    iyy="0.0265621377486244"
                    iyz="-1.10079499865282E-06"
                    izz="0.0129535610833954"/>
        </inertial>
        <visual>
            <origin xyz="0 0 0" rpy="0 0 0"/>
            <geometry>
                <mesh filename="package://assistbot_description/meshes/X3plus/visual/base_link.STL"/>
            </geometry>
            <material name="">
                <color rgba="0 0.7 0 1"/>
            </material>
        </visual>
        <!-- <collision>
            <origin xyz="0 0 0" rpy="0 0 0"/>
            <geometry>
                <mesh filename="package://assistbot_description/meshes/X3/base_link.STL"/>
            </geometry>
        </collision> -->
    </link>
    <joint name="base_joint" type="fixed">
        <parent link="base_footprint"/>
        <child link="base_link"/>
        <origin xyz="0.0 0.0 0.076" rpy="0 0 0"/>
    </joint>
    <joint name="base_imu" type="fixed">
        <parent link="base_link"/>
        <child link="imu_link"/>
        <origin xyz="0.001 0.017 0.0322" rpy="0 3.1415 1.5707"/>
    </joint>
    <link name="front_right_wheel">
        <inertial>
            <origin xyz="1.9051E-06 -2.3183E-07 -0.00064079" rpy="0 0 0"/>
            <mass value="0.051532"/>
            <inertia ixx="1.4595E-05" ixy="-4.3975E-10" ixz="4.415E-10"
                     iyy="1.4594E-05" iyz="-1.7476E-09" izz="2.4264E-05"/>
        </inertial>
        <visual>
            <origin xyz="0 0 0" rpy="0 0 0"/>
            <geometry>
                <mesh filename="package://assistbot_description/meshes/X3/front_right_wheel.STL"/>
            </geometry>
            <material name="">
                <color rgba="0.7 0.7 0.7 1"/>
            </material>
        </visual>
        <collision>
            <origin xyz="0 0 0" rpy="0 0 0"/>
            <geometry>
                <mesh filename="package://assistbot_description/meshes/X3/front_right_wheel.STL"/>
            </geometry>
        </collision>
    </link>
    <joint name="front_right_wheel_joint" type="continuous">
        <origin xyz="0.105 -0.1 -0.0389" rpy="-1.5703 0 3.14159"/>
        <parent link="base_link"/>
        <child link="front_right_wheel"/>
        <axis xyz="0 0 1" rpy="0 0 0"/>
        <limit effort="100" velocity="1"/>
    </joint>
    <link name="front_left_wheel">
        <inertial>
            <origin xyz="2.3728E-06 -9.4228E-07 0.00064068" rpy="0 0 0"/>
            <mass value="0.051543"/>
            <inertia ixx="1.4597E-05" ixy="-4.7945E-10" ixz="-2.4786E-10"
                     iyy="1.4598E-05" iyz="1.7972E-09" izz="2.4267E-05"/>
        </inertial>
        <visual>
            <origin xyz="0 0 0" rpy="0 0 0"/>
            <geometry>
                <mesh filename="package://assistbot_description/meshes/X3/front_left_wheel.STL"/>
            </geometry>
            <material name="">
                <color rgba="0.7 0.7 0.7 1"/>
            </material>
        </visual>
        <collision>
            <origin xyz="0 0 0" rpy="0 0 0"/>
            <geometry>
                <mesh filename="package://assistbot_description/meshes/X3/front_left_wheel.STL"/>
            </geometry>
        </collision>
    </link>
    <joint name="front_left_wheel_joint" type="continuous">
        <origin xyz="0.105 0.1 -0.0389" rpy="1.5703 0 0"/>
        <parent link="base_link"/>
        <child link="front_left_wheel"/>
        <axis xyz="0 0 1" rpy="0 0 0"/>
        <limit effort="100" velocity="1"/>
    </joint>
    <link name="back_right_wheel">
        <inertial>
            <origin xyz="-1.75924169923403E-06 1.28388821071107E-06 -0.000590549296238266" rpy="0 0 0"/>
            <mass value="0.051540174053366"/>
            <inertia ixx="1.45974152250002E-05" ixy="1.94850559178397E-10" ixz="-1.61846387282284E-09"
                     iyy="1.4596501955693E-05" iyz="-6.27904057423818E-10" izz="2.42663091380451E-05"/>
        </inertial>
        <visual>
            <origin xyz="0 0 0" rpy="0 0 0"/>
            <geometry>
                <mesh filename="package://assistbot_description/meshes/X3/back_right_wheel.STL"/>
            </geometry>
            <material name="">
                <color rgba="0.7 0.7 0.7 1"/>
            </material>
        </visual>
        <collision>
            <origin xyz="0 0 0" rpy="0 0 0"/>
            <geometry>
                <mesh filename="package://assistbot_description/meshes/X3/back_right_wheel.STL"/>
            </geometry>
        </collision>
    </link>
    <joint name="back_right_wheel_joint" type="continuous">
        <origin xyz="-0.115 -0.1 -0.03946" rpy="-1.57 0 3.14159"/>
        <parent link="base_link"/>
        <child link="back_right_wheel"/>
        <axis xyz="0 0 1" rpy="0 0 0"/>
        <limit effort="100" velocity="1"/>
    </joint>
    <link name="back_left_wheel">
        <inertial>
            <origin xyz="-4.01213085227115E-07 2.04910264598596E-06 0.000590775697051377" rpy="0 0 0"/>
            <mass value="0.0515309299357028"/>
            <inertia ixx="1.45942986129926E-05" ixy="-3.19787215398093E-10" ixz="1.74943062058915E-09"
                     iyy="1.45948727598913E-05" iyz="1.61769812110049E-10" izz="2.4263683888153E-05"/>
        </inertial>
        <visual>
            <origin xyz="0 0 0" rpy="0 0 0"/>
            <geometry>
                <mesh filename="package://assistbot_description/meshes/X3/back_left_wheel.STL"/>
            </geometry>
            <material name="">
                <color rgba="0.7 0.7 0.7 1"/>
            </material>
        </visual>
        <collision>
            <origin xyz="0 0 0" rpy="0 0 0"/>
            <geometry>
                <mesh filename="package://assistbot_description/meshes/X3/back_left_wheel.STL"/>
            </geometry>
        </collision>
    </link>
    <joint name="back_left_wheel_joint" type="continuous">
        <origin xyz="-0.115 0.1 -0.03954" rpy="1.5703 0 0"/>
        <parent link="base_link"/>
        <child link="back_left_wheel"/>
        <axis xyz="0 0 1" rpy="0 0 0"/>
        <limit effort="100" velocity="1"/>
    </joint>
    <!-- LIDAR -->
     <link name="laser_link">
        <inertial>
            <origin xyz="-0.0193193958962378 0.000338302570666659 -0.01482422577972" rpy="0 0 0"/>
            <mass value="0.0433399617554554"/>
            <inertia
                    ixx="2.03361882296905E-05"
                    ixy="-3.29493708697467E-07"
                    ixz="-9.00810512916648E-06"
                    iyy="4.37540022779682E-05"
                    iyz="-2.16320544253691E-07"
                    izz="4.81888233320734E-05"/>
        </inertial>
        <visual>
            <origin xyz="0 0 0" rpy="0 0 0"/>
            <geometry>
                <mesh filename="package://assistbot_description/meshes/sensor/visual/laser_link.STL"/>
            </geometry>
            <material name="">
                <color rgba="0.7 0.7 0.7 1"/>
            </material>
        </visual>
        <collision>
            <origin xyz="0 0 0" rpy="0 0 0"/>
            <geometry>
                <mesh filename="package://assistbot_description/meshes/sensor/collision/laser_link.STL"/>
            </geometry>
        </collision>
    </link>
    <joint name="laser_joint" type="fixed">
        <origin xyz="0.10478 0 0.0471" rpy="0 0 0"/>
        <parent link="base_link"/>
        <child link="laser_link"/>
    </joint>
    <!-- CAMERA -->
    <link name="camera_link">
        <inertial>
            <origin xyz="-0.00227617338844674 -6.0192031420306E-06 -0.00616567843043764" rpy="0 0 0"/>
            <mass value="0.224346273348015"/>
            <inertia
                    ixx="0.000420259753235012"
                    ixy="2.65423313072081E-08"
                    ixz="-9.20335513714662E-06"
                    iyy="7.89049803518943E-05"
                    iyz="6.08195761013683E-09"
                    izz="0.000414416844201259"/>
        </inertial>
        <visual>
            <origin xyz="0 0 0" rpy="0 0 0"/>
            <geometry>
                <mesh filename="package://assistbot_description/meshes/sensor/visual/camera_link.STL"/>
            </geometry>
            <material name="">
                <color rgba="0.7 0.7 0.7 1"/>
            </material>
        </visual>
        <collision>
            <origin xyz="0 0 0" rpy="0 0 0"/>
            <geometry>
                <mesh filename="package://assistbot_description/meshes/sensor/collision/camera_link.STL"/>
            </geometry>
        </collision>
    </link>
    <joint name="astra_joint" type="fixed">
        <origin xyz="-0.043645 0 0.41955" rpy="0 0 0"/>
        <parent link="base_link"/>
        <child link="camera_link"/>
    </joint>

</robot>

